$ kubectl get events -A --sort-by=.lastTimestamp

NAMESPACE            LAST SEEN   TYPE      REASON                            OBJECT                                                       MESSAGE
default              12m         Normal    Starting                          node/ai-factory-lab-worker                                   
default              12m         Normal    Starting                          node/ai-factory-lab-control-plane                            
default              12m         Normal    NodeHasNoDiskPressure             node/ai-factory-lab-control-plane                            Node ai-factory-lab-control-plane status is now: NodeHasNoDiskPressure
default              12m         Normal    NodeHasSufficientMemory           node/ai-factory-lab-control-plane                            Node ai-factory-lab-control-plane status is now: NodeHasSufficientMemory
default              12m         Normal    NodeHasSufficientPID              node/ai-factory-lab-control-plane                            Node ai-factory-lab-control-plane status is now: NodeHasSufficientPID
default              12m         Normal    NodeAllocatableEnforced           node/ai-factory-lab-control-plane                            Updated Node Allocatable limit across pods
default              12m         Normal    Starting                          node/ai-factory-lab-control-plane                            Starting kubelet.
kube-system          12m         Normal    LeaderElection                    lease/kube-controller-manager                                ai-factory-lab-control-plane_d8d2854b-46a9-49b2-8f86-5e1cdbaebbf5 became leader
kube-system          12m         Normal    LeaderElection                    lease/kube-scheduler                                         ai-factory-lab-control-plane_bc07901a-2e52-47f5-bba9-a16b2c75f185 became leader
default              12m         Normal    RegisteredNode                    node/ai-factory-lab-control-plane                            Node ai-factory-lab-control-plane event: Registered Node ai-factory-lab-control-plane in Controller
kube-system          12m         Warning   NodeNotReady                      pod/etcd-ai-factory-lab-control-plane                        Node is not ready
kube-system          12m         Warning   NodeNotReady                      pod/kube-apiserver-ai-factory-lab-control-plane              Node is not ready
kube-system          12m         Warning   NodeNotReady                      pod/kube-controller-manager-ai-factory-lab-control-plane     Node is not ready
local-path-storage   12m         Normal    SuccessfulCreate                  replicaset/local-path-provisioner-855c7b7774                 Created pod: local-path-provisioner-855c7b7774-nc8km
kube-system          12m         Normal    Scheduled                         pod/kindnet-k7kh7                                            Successfully assigned kube-system/kindnet-k7kh7 to ai-factory-lab-control-plane
kube-system          12m         Normal    SuccessfulCreate                  replicaset/coredns-589f44dc88                                Created pod: coredns-589f44dc88-txpvz
local-path-storage   12m         Normal    ScalingReplicaSet                 deployment/local-path-provisioner                            Scaled up replica set local-path-provisioner-855c7b7774 from 0 to 1
kube-system          12m         Normal    SuccessfulCreate                  replicaset/coredns-589f44dc88                                Created pod: coredns-589f44dc88-vjfjv
kube-system          12m         Normal    ScalingReplicaSet                 deployment/coredns                                           Scaled up replica set coredns-589f44dc88 from 0 to 2
kube-system          12m         Normal    Scheduled                         pod/kube-proxy-t64ff                                         Successfully assigned kube-system/kube-proxy-t64ff to ai-factory-lab-control-plane
kube-system          12m         Warning   FailedScheduling                  pod/coredns-589f44dc88-txpvz                                 0/1 nodes are available: 1 node(s) had untolerated taint(s). no new claims to deallocate, preemption: 0/1 nodes are available: 1 Preemption is not helpful for scheduling.
kube-system          12m         Normal    SuccessfulCreate                  daemonset/kindnet                                            Created pod: kindnet-k7kh7
local-path-storage   12m         Warning   FailedScheduling                  pod/local-path-provisioner-855c7b7774-nc8km                  0/1 nodes are available: 1 node(s) had untolerated taint(s). no new claims to deallocate, preemption: 0/1 nodes are available: 1 Preemption is not helpful for scheduling.
kube-system          12m         Normal    SuccessfulCreate                  daemonset/kube-proxy                                         Created pod: kube-proxy-t64ff
kube-system          12m         Warning   FailedScheduling                  pod/coredns-589f44dc88-vjfjv                                 0/1 nodes are available: 1 node(s) had untolerated taint(s). no new claims to deallocate, preemption: 0/1 nodes are available: 1 Preemption is not helpful for scheduling.
kube-system          12m         Normal    Pulled                            pod/kube-proxy-t64ff                                         Container image "registry.k8s.io/kube-proxy:v1.36.1" already present on machine and can be accessed by the pod
kube-system          12m         Normal    Created                           pod/kube-proxy-t64ff                                         Container created
kube-system          12m         Normal    Started                           pod/kube-proxy-t64ff                                         Container started
default              12m         Normal    NodeHasNoDiskPressure             node/ai-factory-lab-worker                                   Node ai-factory-lab-worker status is now: NodeHasNoDiskPressure
default              12m         Normal    NodeHasSufficientMemory           node/ai-factory-lab-worker                                   Node ai-factory-lab-worker status is now: NodeHasSufficientMemory
default              12m         Normal    NodeHasSufficientPID              node/ai-factory-lab-worker                                   Node ai-factory-lab-worker status is now: NodeHasSufficientPID
default              12m         Normal    Starting                          node/ai-factory-lab-worker                                   Starting kubelet.
default              12m         Normal    NodeAllocatableEnforced           node/ai-factory-lab-worker                                   Updated Node Allocatable limit across pods
kube-system          12m         Normal    Scheduled                         pod/kube-proxy-rxmgv                                         Successfully assigned kube-system/kube-proxy-rxmgv to ai-factory-lab-worker
kube-system          12m         Normal    SuccessfulCreate                  daemonset/kube-proxy                                         Created pod: kube-proxy-rxmgv
kube-system          12m         Normal    SuccessfulCreate                  daemonset/kindnet                                            Created pod: kindnet-h6w2d
kube-system          12m         Normal    Scheduled                         pod/kindnet-h6w2d                                            Successfully assigned kube-system/kindnet-h6w2d to ai-factory-lab-worker
kube-system          12m         Normal    Started                           pod/kube-proxy-rxmgv                                         Container started
kube-system          12m         Normal    Created                           pod/kindnet-h6w2d                                            Container created
kube-system          12m         Normal    Started                           pod/kindnet-h6w2d                                            Container started
kube-system          12m         Normal    Pulled                            pod/kindnet-h6w2d                                            Container image "docker.io/kindest/kindnetd:v20260528-9350166c" already present on machine and can be accessed by the pod
kube-system          12m         Normal    Created                           pod/kube-proxy-rxmgv                                         Container created
kube-system          12m         Normal    Pulled                            pod/kube-proxy-rxmgv                                         Container image "registry.k8s.io/kube-proxy:v1.36.1" already present on machine and can be accessed by the pod
kube-system          12m         Warning   FailedScheduling                  pod/kwok-controller-585d894967-6j92j                         0/2 nodes are available: 2 node(s) had untolerated taint(s). no new claims to deallocate, preemption: 0/2 nodes are available: 2 Preemption is not helpful for scheduling.
kube-system          12m         Normal    ScalingReplicaSet                 deployment/kwok-controller                                   Scaled up replica set kwok-controller-585d894967 from 0 to 1
kube-system          12m         Normal    SuccessfulCreate                  replicaset/kwok-controller-585d894967                        Created pod: kwok-controller-585d894967-6j92j
default              12m         Normal    RegisteredNode                    node/ai-factory-lab-worker                                   Node ai-factory-lab-worker event: Registered Node ai-factory-lab-worker in Controller
default              12m         Normal    NodeReady                         node/ai-factory-lab-control-plane                            Node ai-factory-lab-control-plane status is now: NodeReady
kube-system          12m         Normal    Scheduled                         pod/coredns-589f44dc88-vjfjv                                 Successfully assigned kube-system/coredns-589f44dc88-vjfjv to ai-factory-lab-control-plane
kube-system          12m         Normal    Scheduled                         pod/coredns-589f44dc88-txpvz                                 Successfully assigned kube-system/coredns-589f44dc88-txpvz to ai-factory-lab-control-plane
local-path-storage   12m         Normal    Scheduled                         pod/local-path-provisioner-855c7b7774-nc8km                  Successfully assigned local-path-storage/local-path-provisioner-855c7b7774-nc8km to ai-factory-lab-control-plane
kube-system          12m         Normal    Started                           pod/coredns-589f44dc88-txpvz                                 Container started
local-path-storage   12m         Normal    Started                           pod/local-path-provisioner-855c7b7774-nc8km                  Container started
local-path-storage   12m         Normal    Pulled                            pod/local-path-provisioner-855c7b7774-nc8km                  Container image "docker.io/kindest/local-path-provisioner:v20260521-9fb22683" already present on machine and can be accessed by the pod
kube-system          12m         Normal    Started                           pod/coredns-589f44dc88-vjfjv                                 Container started
kube-system          12m         Warning   Unhealthy                         pod/coredns-589f44dc88-vjfjv                                 Readiness probe failed: Get "http://10.244.0.2:8181/ready": dial tcp 10.244.0.2:8181: connect: connection refused
kube-system          12m         Normal    Created                           pod/coredns-589f44dc88-vjfjv                                 Container created
local-path-storage   12m         Normal    Created                           pod/local-path-provisioner-855c7b7774-nc8km                  Container created
kube-system          12m         Normal    Pulled                            pod/coredns-589f44dc88-txpvz                                 Container image "registry.k8s.io/coredns/coredns:v1.14.2" already present on machine and can be accessed by the pod
kube-system          12m         Normal    Pulled                            pod/coredns-589f44dc88-vjfjv                                 Container image "registry.k8s.io/coredns/coredns:v1.14.2" already present on machine and can be accessed by the pod
kube-system          12m         Normal    Created                           pod/coredns-589f44dc88-txpvz                                 Container created
kube-system          12m         Warning   Unhealthy                         pod/coredns-589f44dc88-txpvz                                 Readiness probe failed: Get "http://10.244.0.4:8181/ready": dial tcp 10.244.0.4:8181: connect: connection refused
kube-system          12m         Normal    Scheduled                         pod/kwok-controller-585d894967-6j92j                         Successfully assigned kube-system/kwok-controller-585d894967-6j92j to ai-factory-lab-worker
default              12m         Normal    NodeReady                         node/ai-factory-lab-worker                                   Node ai-factory-lab-worker status is now: NodeReady
kube-system          12m         Normal    Pulling                           pod/kwok-controller-585d894967-6j92j                         Pulling image "registry.k8s.io/kwok/kwok:v0.7.0"
kube-system          11m         Normal    Pulled                            pod/kwok-controller-585d894967-6j92j                         Successfully pulled image "registry.k8s.io/kwok/kwok:v0.7.0" in 6.339s (6.339s including waiting). Image size: 43535882 bytes.
kube-system          11m         Normal    Started                           pod/kwok-controller-585d894967-6j92j                         Container started
kube-system          11m         Normal    Created                           pod/kwok-controller-585d894967-6j92j                         Container created
gpu-operator         11m         Normal    SuccessfulCreate                  replicaset/topology-server-7d47555bd8                        Created pod: topology-server-7d47555bd8-pj4zs
gpu-operator         11m         Normal    ScalingReplicaSet                 deployment/topology-server                                   Scaled up replica set topology-server-7d47555bd8 from 0 to 1
gpu-operator         11m         Normal    Scheduled                         pod/status-updater-6559cdbd76-mtcnd                          Successfully assigned gpu-operator/status-updater-6559cdbd76-mtcnd to ai-factory-lab-worker
gpu-operator         11m         Normal    SuccessfulCreate                  replicaset/status-updater-6559cdbd76                         Created pod: status-updater-6559cdbd76-mtcnd
gpu-operator         11m         Normal    ScalingReplicaSet                 deployment/status-updater                                    Scaled up replica set status-updater-6559cdbd76 from 0 to 1
gpu-operator         11m         Normal    Scheduled                         pod/topology-server-7d47555bd8-pj4zs                         Successfully assigned gpu-operator/topology-server-7d47555bd8-pj4zs to ai-factory-lab-worker
gpu-operator         11m         Normal    ScalingReplicaSet                 deployment/kwok-gpu-device-plugin                            Scaled up replica set kwok-gpu-device-plugin-657c69fcd from 0 to 1
gpu-operator         11m         Normal    Scheduled                         pod/kwok-gpu-device-plugin-657c69fcd-s2dlf                   Successfully assigned gpu-operator/kwok-gpu-device-plugin-657c69fcd-s2dlf to ai-factory-lab-worker
gpu-operator         11m         Normal    SuccessfulCreate                  replicaset/kwok-gpu-device-plugin-657c69fcd                  Created pod: kwok-gpu-device-plugin-657c69fcd-s2dlf
gpu-operator         11m         Normal    Pulling                           pod/kwok-gpu-device-plugin-657c69fcd-s2dlf                   Pulling image "gcr.io/run-ai-staging/fake-gpu-operator/kwok-gpu-device-plugin:0.0.59"
gpu-operator         11m         Normal    Pulling                           pod/status-updater-6559cdbd76-mtcnd                          Pulling image "gcr.io/run-ai-staging/fake-gpu-operator/status-updater:0.0.59"
gpu-operator         11m         Normal    Pulling                           pod/topology-server-7d47555bd8-pj4zs                         Pulling image "gcr.io/run-ai-staging/fake-gpu-operator/topology-server:0.0.59"
gpu-operator         11m         Normal    Pulled                            pod/status-updater-6559cdbd76-mtcnd                          Successfully pulled image "gcr.io/run-ai-staging/fake-gpu-operator/status-updater:0.0.59" in 10.881s (10.881s including waiting). Image size: 55789904 bytes.
gpu-operator         11m         Normal    Created                           pod/status-updater-6559cdbd76-mtcnd                          Container created
gpu-operator         11m         Normal    Started                           pod/status-updater-6559cdbd76-mtcnd                          Container started
gpu-operator         11m         Normal    Started                           pod/topology-server-7d47555bd8-pj4zs                         Container started
gpu-operator         11m         Normal    Pulled                            pod/topology-server-7d47555bd8-pj4zs                         Successfully pulled image "gcr.io/run-ai-staging/fake-gpu-operator/topology-server:0.0.59" in 7.689s (18.553s including waiting). Image size: 54168648 bytes.
gpu-operator         11m         Normal    Created                           pod/topology-server-7d47555bd8-pj4zs                         Container created
kube-system          11m         Normal    SuccessfulCreate                  daemonset/kindnet                                            Created pod: kindnet-c7j8m
kube-system          11m         Normal    Scheduled                         pod/kube-proxy-rkjlz                                         Successfully assigned kube-system/kube-proxy-rkjlz to kwok-gpu-a100-1
gpu-operator         11m         Normal    Pulled                            pod/kwok-gpu-device-plugin-657c69fcd-s2dlf                   Successfully pulled image "gcr.io/run-ai-staging/fake-gpu-operator/kwok-gpu-device-plugin:0.0.59" in 7.813s (26.355s including waiting). Image size: 55588961 bytes.
gpu-operator         11m         Normal    SuccessfulCreate                  replicaset/nvidia-dcgm-exporter-kwok-gpu-a100-0-56d7f644cd   Created pod: nvidia-dcgm-exporter-kwok-gpu-a100-0-56d7f644cd-rxqcm
gpu-operator         11m         Normal    ScalingReplicaSet                 deployment/nvidia-dcgm-exporter-kwok-gpu-a100-0              Scaled up replica set nvidia-dcgm-exporter-kwok-gpu-a100-0-56d7f644cd from 0 to 1
gpu-operator         11m         Normal    Scheduled                         pod/nvidia-dcgm-exporter-kwok-gpu-a100-1-78f6456845-7zcl9    Successfully assigned gpu-operator/nvidia-dcgm-exporter-kwok-gpu-a100-1-78f6456845-7zcl9 to ai-factory-lab-worker
gpu-operator         11m         Normal    Scheduled                         pod/nvidia-dcgm-exporter-kwok-gpu-a100-0-56d7f644cd-rxqcm    Successfully assigned gpu-operator/nvidia-dcgm-exporter-kwok-gpu-a100-0-56d7f644cd-rxqcm to ai-factory-lab-worker
kube-system          11m         Normal    SuccessfulCreate                  daemonset/kube-proxy                                         Created pod: kube-proxy-rt2vr
kube-system          11m         Normal    Scheduled                         pod/kube-proxy-rt2vr                                         Successfully assigned kube-system/kube-proxy-rt2vr to kwok-gpu-a100-0
kube-system          11m         Normal    Scheduled                         pod/kindnet-7sf6q                                            Successfully assigned kube-system/kindnet-7sf6q to kwok-gpu-a100-1
kube-system          11m         Normal    SuccessfulCreate                  daemonset/kube-proxy                                         Created pod: kube-proxy-rkjlz
gpu-operator         11m         Normal    SuccessfulCreate                  replicaset/nvidia-dcgm-exporter-kwok-gpu-a100-1-78f6456845   Created pod: nvidia-dcgm-exporter-kwok-gpu-a100-1-78f6456845-7zcl9
gpu-operator         11m         Normal    ScalingReplicaSet                 deployment/nvidia-dcgm-exporter-kwok-gpu-a100-1              Scaled up replica set nvidia-dcgm-exporter-kwok-gpu-a100-1-78f6456845 from 0 to 1
kube-system          11m         Normal    Scheduled                         pod/kindnet-c7j8m                                            Successfully assigned kube-system/kindnet-c7j8m to kwok-gpu-a100-0
gpu-operator         11m         Normal    Started                           pod/kwok-gpu-device-plugin-657c69fcd-s2dlf                   Container started
gpu-operator         11m         Normal    Created                           pod/kwok-gpu-device-plugin-657c69fcd-s2dlf                   Container created
kube-system          11m         Normal    SuccessfulCreate                  daemonset/kindnet                                            Created pod: kindnet-7sf6q
gpu-operator         11m         Normal    ScalingReplicaSet                 deployment/nvidia-dcgm-exporter-kwok-gpu-h100-0              Scaled up replica set nvidia-dcgm-exporter-kwok-gpu-h100-0-b5cbf5dff from 0 to 1
gpu-operator         11m         Normal    Pulling                           pod/nvidia-dcgm-exporter-kwok-gpu-a100-0-56d7f644cd-rxqcm    Pulling image "gcr.io/run-ai-staging/fake-gpu-operator/status-exporter:0.0.59"
gpu-operator         11m         Normal    SuccessfulCreate                  replicaset/nvidia-dcgm-exporter-kwok-gpu-h100-0-b5cbf5dff    Created pod: nvidia-dcgm-exporter-kwok-gpu-h100-0-b5cbf5dff-xcrwx
kube-system          11m         Normal    Scheduled                         pod/kindnet-tqgwt                                            Successfully assigned kube-system/kindnet-tqgwt to kwok-gpu-l40s-0
gpu-operator         11m         Normal    Scheduled                         pod/nvidia-dcgm-exporter-kwok-gpu-l40s-0-7b9b44f89c-dbjjm    Successfully assigned gpu-operator/nvidia-dcgm-exporter-kwok-gpu-l40s-0-7b9b44f89c-dbjjm to ai-factory-lab-worker
kube-system          11m         Normal    Scheduled                         pod/kindnet-wcddc                                            Successfully assigned kube-system/kindnet-wcddc to kwok-gpu-l40s-1
kube-system          11m         Normal    SuccessfulCreate                  daemonset/kindnet                                            Created pod: kindnet-8tcbl
kube-system          11m         Normal    SuccessfulCreate                  daemonset/kindnet                                            Created pod: kindnet-tqgwt
kube-system          11m         Normal    SuccessfulCreate                  daemonset/kindnet                                            Created pod: kindnet-wcddc
kube-system          11m         Normal    Scheduled                         pod/kube-proxy-2rvnm                                         Successfully assigned kube-system/kube-proxy-2rvnm to kwok-gpu-l40s-1
gpu-operator         11m         Normal    SuccessfulCreate                  replicaset/nvidia-dcgm-exporter-kwok-gpu-l40s-0-7b9b44f89c   Created pod: nvidia-dcgm-exporter-kwok-gpu-l40s-0-7b9b44f89c-dbjjm
gpu-operator         11m         Normal    ScalingReplicaSet                 deployment/nvidia-dcgm-exporter-kwok-gpu-l40s-0              Scaled up replica set nvidia-dcgm-exporter-kwok-gpu-l40s-0-7b9b44f89c from 0 to 1
gpu-operator         11m         Normal    Scheduled                         pod/nvidia-dcgm-exporter-kwok-gpu-l40s-1-588cf5c578-bhnwf    Successfully assigned gpu-operator/nvidia-dcgm-exporter-kwok-gpu-l40s-1-588cf5c578-bhnwf to ai-factory-lab-worker
kube-system          11m         Normal    Scheduled                         pod/kube-proxy-c5jbw                                         Successfully assigned kube-system/kube-proxy-c5jbw to kwok-gpu-l40s-0
kube-system          11m         Normal    Scheduled                         pod/kube-proxy-fhgst                                         Successfully assigned kube-system/kube-proxy-fhgst to kwok-gpu-h100-0
kube-system          11m         Normal    SuccessfulCreate                  daemonset/kube-proxy                                         Created pod: kube-proxy-fhgst
kube-system          11m         Normal    SuccessfulCreate                  daemonset/kube-proxy                                         Created pod: kube-proxy-c5jbw
kube-system          11m         Normal    Scheduled                         pod/kindnet-8tcbl                                            Successfully assigned kube-system/kindnet-8tcbl to kwok-gpu-h100-0
gpu-operator         11m         Normal    SuccessfulCreate                  replicaset/nvidia-dcgm-exporter-kwok-gpu-l40s-1-588cf5c578   Created pod: nvidia-dcgm-exporter-kwok-gpu-l40s-1-588cf5c578-bhnwf
gpu-operator         11m         Normal    ScalingReplicaSet                 deployment/nvidia-dcgm-exporter-kwok-gpu-l40s-1              Scaled up replica set nvidia-dcgm-exporter-kwok-gpu-l40s-1-588cf5c578 from 0 to 1
kube-system          11m         Normal    SuccessfulCreate                  daemonset/kube-proxy                                         Created pod: kube-proxy-2rvnm
gpu-operator         11m         Normal    Pulling                           pod/nvidia-dcgm-exporter-kwok-gpu-a100-1-78f6456845-7zcl9    Pulling image "gcr.io/run-ai-staging/fake-gpu-operator/status-exporter:0.0.59"
gpu-operator         11m         Normal    Scheduled                         pod/nvidia-dcgm-exporter-kwok-gpu-h100-0-b5cbf5dff-xcrwx     Successfully assigned gpu-operator/nvidia-dcgm-exporter-kwok-gpu-h100-0-b5cbf5dff-xcrwx to ai-factory-lab-worker
gpu-operator         11m         Normal    Pulling                           pod/nvidia-dcgm-exporter-kwok-gpu-l40s-1-588cf5c578-bhnwf    Pulling image "gcr.io/run-ai-staging/fake-gpu-operator/status-exporter:0.0.59"
gpu-operator         11m         Normal    Pulling                           pod/nvidia-dcgm-exporter-kwok-gpu-h100-0-b5cbf5dff-xcrwx     Pulling image "gcr.io/run-ai-staging/fake-gpu-operator/status-exporter:0.0.59"
gpu-operator         11m         Normal    Pulling                           pod/nvidia-dcgm-exporter-kwok-gpu-l40s-0-7b9b44f89c-dbjjm    Pulling image "gcr.io/run-ai-staging/fake-gpu-operator/status-exporter:0.0.59"
default              11m         Normal    RegisteredNode                    node/kwok-gpu-a100-1                                         Node kwok-gpu-a100-1 event: Registered Node kwok-gpu-a100-1 in Controller
default              11m         Normal    RegisteredNode                    node/kwok-gpu-l40s-0                                         Node kwok-gpu-l40s-0 event: Registered Node kwok-gpu-l40s-0 in Controller
default              11m         Normal    RegisteredNode                    node/kwok-gpu-h100-0                                         Node kwok-gpu-h100-0 event: Registered Node kwok-gpu-h100-0 in Controller
default              11m         Normal    RegisteredNode                    node/kwok-gpu-l40s-1                                         Node kwok-gpu-l40s-1 event: Registered Node kwok-gpu-l40s-1 in Controller
default              11m         Normal    RegisteredNode                    node/kwok-gpu-a100-0                                         Node kwok-gpu-a100-0 event: Registered Node kwok-gpu-a100-0 in Controller
gpu-operator         11m         Normal    Started                           pod/nvidia-dcgm-exporter-kwok-gpu-a100-0-56d7f644cd-rxqcm    Container started
gpu-operator         11m         Normal    Created                           pod/nvidia-dcgm-exporter-kwok-gpu-a100-0-56d7f644cd-rxqcm    Container created
gpu-operator         11m         Normal    Pulled                            pod/nvidia-dcgm-exporter-kwok-gpu-a100-0-56d7f644cd-rxqcm    Successfully pulled image "gcr.io/run-ai-staging/fake-gpu-operator/status-exporter:0.0.59" in 8.285s (8.285s including waiting). Image size: 54523436 bytes.
gpu-operator         11m         Normal    Pulled                            pod/nvidia-dcgm-exporter-kwok-gpu-h100-0-b5cbf5dff-xcrwx     Successfully pulled image "gcr.io/run-ai-staging/fake-gpu-operator/status-exporter:0.0.59" in 901ms (9.378s including waiting). Image size: 54523436 bytes.
gpu-operator         11m         Normal    Pulled                            pod/nvidia-dcgm-exporter-kwok-gpu-a100-1-78f6456845-7zcl9    Successfully pulled image "gcr.io/run-ai-staging/fake-gpu-operator/status-exporter:0.0.59" in 882ms (9.09s including waiting). Image size: 54523436 bytes.
gpu-operator         11m         Normal    Created                           pod/nvidia-dcgm-exporter-kwok-gpu-h100-0-b5cbf5dff-xcrwx     Container created
gpu-operator         11m         Normal    Created                           pod/nvidia-dcgm-exporter-kwok-gpu-a100-1-78f6456845-7zcl9    Container created
gpu-operator         11m         Normal    Started                           pod/nvidia-dcgm-exporter-kwok-gpu-a100-1-78f6456845-7zcl9    Container started
gpu-operator         11m         Normal    Started                           pod/nvidia-dcgm-exporter-kwok-gpu-h100-0-b5cbf5dff-xcrwx     Container started
gpu-operator         11m         Normal    Created                           pod/nvidia-dcgm-exporter-kwok-gpu-l40s-0-7b9b44f89c-dbjjm    Container created
gpu-operator         11m         Normal    Pulled                            pod/nvidia-dcgm-exporter-kwok-gpu-l40s-0-7b9b44f89c-dbjjm    Successfully pulled image "gcr.io/run-ai-staging/fake-gpu-operator/status-exporter:0.0.59" in 954ms (10.143s including waiting). Image size: 54523436 bytes.
gpu-operator         11m         Normal    Created                           pod/nvidia-dcgm-exporter-kwok-gpu-l40s-1-588cf5c578-bhnwf    Container created
gpu-operator         11m         Normal    Started                           pod/nvidia-dcgm-exporter-kwok-gpu-l40s-0-7b9b44f89c-dbjjm    Container started
gpu-operator         11m         Normal    Pulled                            pod/nvidia-dcgm-exporter-kwok-gpu-l40s-1-588cf5c578-bhnwf    Successfully pulled image "gcr.io/run-ai-staging/fake-gpu-operator/status-exporter:0.0.59" in 854ms (10.914s including waiting). Image size: 54523436 bytes.
gpu-operator         11m         Normal    Started                           pod/nvidia-dcgm-exporter-kwok-gpu-l40s-1-588cf5c578-bhnwf    Container started
gpu-demo             6m4s        Normal    Scheduled                         pod/queue-pressure-6696ccff7b-wbql7                          Successfully assigned gpu-demo/queue-pressure-6696ccff7b-wbql7 to kwok-gpu-a100-0
gpu-demo             6m4s        Normal    Scheduled                         pod/queue-pressure-6696ccff7b-qmv82                          Successfully assigned gpu-demo/queue-pressure-6696ccff7b-qmv82 to kwok-gpu-a100-1
gpu-demo             6m4s        Normal    Scheduled                         pod/cuda-batch-small                                         Successfully assigned gpu-demo/cuda-batch-small to kwok-gpu-a100-1
gpu-demo             6m4s        Normal    Scheduled                         pod/queue-pressure-6696ccff7b-xs4v8                          Successfully assigned gpu-demo/queue-pressure-6696ccff7b-xs4v8 to kwok-gpu-a100-1
gpu-demo             6m4s        Normal    Scheduled                         pod/queue-pressure-6696ccff7b-xqvjj                          Successfully assigned gpu-demo/queue-pressure-6696ccff7b-xqvjj to kwok-gpu-a100-0
gpu-demo             6m4s        Normal    Scheduled                         pod/queue-pressure-6696ccff7b-br8xx                          Successfully assigned gpu-demo/queue-pressure-6696ccff7b-br8xx to kwok-gpu-h100-0
gpu-demo             6m4s        Normal    Scheduled                         pod/queue-pressure-6696ccff7b-wlh2w                          Successfully assigned gpu-demo/queue-pressure-6696ccff7b-wlh2w to kwok-gpu-h100-0
gpu-demo             6m4s        Normal    SuccessfulCreate                  replicaset/queue-pressure-6696ccff7b                         Created pod: queue-pressure-6696ccff7b-wbql7
gpu-demo             6m4s        Normal    Scheduled                         pod/queue-pressure-6696ccff7b-wjqgm                          Successfully assigned gpu-demo/queue-pressure-6696ccff7b-wjqgm to kwok-gpu-h100-0
gpu-demo             6m4s        Normal    SuccessfulCreate                  replicaset/queue-pressure-6696ccff7b                         Created pod: queue-pressure-6696ccff7b-hmlv4
gpu-demo             6m4s        Normal    Scheduled                         pod/queue-pressure-6696ccff7b-2xx4s                          Successfully assigned gpu-demo/queue-pressure-6696ccff7b-2xx4s to kwok-gpu-l40s-0
gpu-demo             6m4s        Normal    Scheduled                         pod/queue-pressure-6696ccff7b-th6vl                          Successfully assigned gpu-demo/queue-pressure-6696ccff7b-th6vl to kwok-gpu-a100-0
gpu-demo             6m4s        Normal    Scheduled                         pod/queue-pressure-6696ccff7b-sxbl5                          Successfully assigned gpu-demo/queue-pressure-6696ccff7b-sxbl5 to kwok-gpu-a100-0
gpu-demo             6m4s        Normal    Scheduled                         pod/queue-pressure-6696ccff7b-sbt98                          Successfully assigned gpu-demo/queue-pressure-6696ccff7b-sbt98 to kwok-gpu-a100-0
gpu-demo             6m4s        Normal    Scheduled                         pod/queue-pressure-6696ccff7b-45nh8                          Successfully assigned gpu-demo/queue-pressure-6696ccff7b-45nh8 to kwok-gpu-l40s-0
gpu-demo             6m4s        Normal    Scheduled                         pod/queue-pressure-6696ccff7b-4whnq                          Successfully assigned gpu-demo/queue-pressure-6696ccff7b-4whnq to kwok-gpu-h100-0
gpu-demo             6m4s        Normal    SuccessfulCreate                  replicaset/queue-pressure-6696ccff7b                         Created pod: queue-pressure-6696ccff7b-f9jm8
gpu-demo             6m4s        Normal    Scheduled                         pod/queue-pressure-6696ccff7b-5rnpz                          Successfully assigned gpu-demo/queue-pressure-6696ccff7b-5rnpz to kwok-gpu-a100-0
gpu-demo             6m4s        Normal    SuccessfulCreate                  replicaset/queue-pressure-6696ccff7b                         Created pod: queue-pressure-6696ccff7b-dnsgw
gpu-demo             6m4s        Normal    SuccessfulCreate                  replicaset/queue-pressure-6696ccff7b                         Created pod: queue-pressure-6696ccff7b-xs4v8
gpu-demo             6m4s        Normal    Scheduled                         pod/queue-pressure-6696ccff7b-679bk                          Successfully assigned gpu-demo/queue-pressure-6696ccff7b-679bk to kwok-gpu-h100-0
gpu-demo             6m4s        Normal    Scheduled                         pod/queue-pressure-6696ccff7b-9tmhg                          Successfully assigned gpu-demo/queue-pressure-6696ccff7b-9tmhg to kwok-gpu-a100-0
gpu-demo             6m4s        Normal    Scheduled                         pod/queue-pressure-6696ccff7b-p5pzz                          Successfully assigned gpu-demo/queue-pressure-6696ccff7b-p5pzz to kwok-gpu-l40s-0
gpu-demo             6m4s        Normal    Scheduled                         pod/queue-pressure-6696ccff7b-n8p4x                          Successfully assigned gpu-demo/queue-pressure-6696ccff7b-n8p4x to kwok-gpu-a100-1
gpu-demo             6m4s        Normal    SuccessfulCreate                  replicaset/queue-pressure-6696ccff7b                         Created pod: queue-pressure-6696ccff7b-5rnpz
gpu-demo             6m4s        Normal    SuccessfulCreate                  replicaset/queue-pressure-6696ccff7b                         Created pod: queue-pressure-6696ccff7b-45nh8
gpu-demo             6m4s        Normal    SuccessfulCreate                  replicaset/queue-pressure-6696ccff7b                         Created pod: queue-pressure-6696ccff7b-p5pzz
gpu-demo             6m4s        Normal    Scheduled                         pod/queue-pressure-6696ccff7b-876px                          Successfully assigned gpu-demo/queue-pressure-6696ccff7b-876px to kwok-gpu-a100-1
gpu-demo             6m4s        Normal    Scheduled                         pod/queue-pressure-6696ccff7b-kthdr                          Successfully assigned gpu-demo/queue-pressure-6696ccff7b-kthdr to kwok-gpu-a100-1
gpu-demo             6m4s        Normal    Scheduled                         pod/queue-pressure-6696ccff7b-jxrph                          Successfully assigned gpu-demo/queue-pressure-6696ccff7b-jxrph to kwok-gpu-h100-0
gpu-demo             6m4s        Normal    SuccessfulCreate                  replicaset/queue-pressure-6696ccff7b                         Created pod: queue-pressure-6696ccff7b-hgbr5
gpu-demo             6m4s        Normal    Scheduled                         pod/queue-pressure-6696ccff7b-8rdp8                          Successfully assigned gpu-demo/queue-pressure-6696ccff7b-8rdp8 to kwok-gpu-l40s-0
gpu-demo             6m4s        Normal    ScalingReplicaSet                 deployment/queue-pressure                                    Scaled up replica set queue-pressure-6696ccff7b from 0 to 40
gpu-demo             6m4s        Normal    Scheduled                         pod/queue-pressure-6696ccff7b-hmlv4                          Successfully assigned gpu-demo/queue-pressure-6696ccff7b-hmlv4 to kwok-gpu-h100-0
gpu-demo             6m4s        Normal    Scheduled                         pod/queue-pressure-6696ccff7b-hjb87                          Successfully assigned gpu-demo/queue-pressure-6696ccff7b-hjb87 to kwok-gpu-l40s-1
gpu-demo             6m4s        Normal    Scheduled                         pod/queue-pressure-6696ccff7b-hgbr5                          Successfully assigned gpu-demo/queue-pressure-6696ccff7b-hgbr5 to kwok-gpu-a100-1
gpu-demo             6m4s        Normal    Scheduled                         pod/queue-pressure-6696ccff7b-frt89                          Successfully assigned gpu-demo/queue-pressure-6696ccff7b-frt89 to kwok-gpu-a100-0
gpu-demo             6m4s        Normal    Scheduled                         pod/queue-pressure-6696ccff7b-fl296                          Successfully assigned gpu-demo/queue-pressure-6696ccff7b-fl296 to kwok-gpu-l40s-1
gpu-demo             6m4s        Normal    Scheduled                         pod/queue-pressure-6696ccff7b-f9jm8                          Successfully assigned gpu-demo/queue-pressure-6696ccff7b-f9jm8 to kwok-gpu-l40s-1
gpu-demo             6m4s        Normal    Scheduled                         pod/queue-pressure-6696ccff7b-drpx4                          Successfully assigned gpu-demo/queue-pressure-6696ccff7b-drpx4 to kwok-gpu-a100-1
gpu-demo             6m4s        Normal    Scheduled                         pod/queue-pressure-6696ccff7b-dnsgw                          Successfully assigned gpu-demo/queue-pressure-6696ccff7b-dnsgw to kwok-gpu-l40s-1
gpu-demo             6m3s        Normal    Scheduled                         pod/queue-pressure-6696ccff7b-25phl                          Successfully assigned gpu-demo/queue-pressure-6696ccff7b-25phl to kwok-gpu-h100-0
gpu-demo             6m2s        Normal    SuccessfulCreate                  replicaset/queue-pressure-6696ccff7b                         (combined from similar events): Created pod: queue-pressure-6696ccff7b-br8xx
kube-system          3m38s       Normal    Started                           pod/kindnet-k7kh7                                            Container started
kube-system          3m38s       Normal    Created                           pod/kindnet-k7kh7                                            Container created
kube-system          3m38s       Normal    Pulled                            pod/kindnet-k7kh7                                            Container image "docker.io/kindest/kindnetd:v20260528-9350166c" already present on machine and can be accessed by the pod
gpu-operator         81s         Warning   FailedToRetrieveImagePullSecret   pod/nvidia-dcgm-exporter-kwok-gpu-l40s-1-588cf5c578-bhnwf    Unable to retrieve some image pull secrets (gcr-secret); attempting to pull the image may not succeed.
gpu-operator         60s         Warning   FailedToRetrieveImagePullSecret   pod/kwok-gpu-device-plugin-657c69fcd-s2dlf                   Unable to retrieve some image pull secrets (gcr-secret); attempting to pull the image may not succeed.
gpu-demo             58s         Warning   FailedScheduling                  pod/cuda-needs-b200                                          0/7 nodes are available: 1 node(s) had untolerated taint(s), 6 node(s) didn't match Pod's node affinity/selector. no new claims to deallocate, preemption: 0/7 nodes are available: 7 Preemption is not helpful for scheduling.
gpu-demo             58s         Warning   FailedScheduling                  pod/queue-pressure-6696ccff7b-xx9lz                          0/7 nodes are available: 1 node(s) had untolerated taint(s), 6 Insufficient nvidia.com/gpu. no new claims to deallocate, preemption: 0/7 nodes are available: 2 Preemption is not helpful for scheduling, 5 No preemption victims found for incoming pod.
gpu-demo             58s         Warning   FailedScheduling                  pod/queue-pressure-6696ccff7b-rk4hr                          0/7 nodes are available: 1 node(s) had untolerated taint(s), 6 Insufficient nvidia.com/gpu. no new claims to deallocate, preemption: 0/7 nodes are available: 2 Preemption is not helpful for scheduling, 5 No preemption victims found for incoming pod.
gpu-demo             58s         Warning   FailedScheduling                  pod/queue-pressure-6696ccff7b-5xngp                          0/7 nodes are available: 1 node(s) had untolerated taint(s), 6 Insufficient nvidia.com/gpu. no new claims to deallocate, preemption: 0/7 nodes are available: 2 Preemption is not helpful for scheduling, 5 No preemption victims found for incoming pod.
gpu-demo             58s         Warning   FailedScheduling                  pod/queue-pressure-6696ccff7b-bwwdq                          0/7 nodes are available: 1 node(s) had untolerated taint(s), 6 Insufficient nvidia.com/gpu. no new claims to deallocate, preemption: 0/7 nodes are available: 2 Preemption is not helpful for scheduling, 5 No preemption victims found for incoming pod.
gpu-demo             58s         Warning   FailedScheduling                  pod/queue-pressure-6696ccff7b-kwqm9                          0/7 nodes are available: 1 node(s) had untolerated taint(s), 6 Insufficient nvidia.com/gpu. no new claims to deallocate, preemption: 0/7 nodes are available: 2 Preemption is not helpful for scheduling, 5 No preemption victims found for incoming pod.
gpu-demo             58s         Warning   FailedScheduling                  pod/queue-pressure-6696ccff7b-vqst9                          0/7 nodes are available: 1 node(s) had untolerated taint(s), 6 Insufficient nvidia.com/gpu. no new claims to deallocate, preemption: 0/7 nodes are available: 2 Preemption is not helpful for scheduling, 5 No preemption victims found for incoming pod.
gpu-demo             58s         Warning   FailedScheduling                  pod/queue-pressure-6696ccff7b-2pqzw                          0/7 nodes are available: 1 node(s) had untolerated taint(s), 6 Insufficient nvidia.com/gpu. no new claims to deallocate, preemption: 0/7 nodes are available: 2 Preemption is not helpful for scheduling, 5 No preemption victims found for incoming pod.
gpu-demo             58s         Warning   FailedScheduling                  pod/queue-pressure-6696ccff7b-xpnn6                          0/7 nodes are available: 1 node(s) had untolerated taint(s), 6 Insufficient nvidia.com/gpu. no new claims to deallocate, preemption: 0/7 nodes are available: 2 Preemption is not helpful for scheduling, 5 No preemption victims found for incoming pod.
gpu-demo             58s         Warning   FailedScheduling                  pod/cuda-train-16gpu                                         0/7 nodes are available: 1 node(s) had untolerated taint(s), 6 Insufficient nvidia.com/gpu. no new claims to deallocate, preemption: 0/7 nodes are available: 7 Preemption is not helpful for scheduling.
gpu-demo             58s         Warning   FailedScheduling                  pod/queue-pressure-6696ccff7b-bm4rb                          0/7 nodes are available: 1 node(s) had untolerated taint(s), 6 Insufficient nvidia.com/gpu. no new claims to deallocate, preemption: 0/7 nodes are available: 2 Preemption is not helpful for scheduling, 5 No preemption victims found for incoming pod.
kube-system          50s         Warning   BackOff                           pod/kindnet-k7kh7                                            Back-off restarting failed container kindnet-cni in pod kindnet-k7kh7_kube-system(da2c53ba-11fa-435d-a370-b4ee54c611e0)
gpu-operator         47s         Warning   FailedToRetrieveImagePullSecret   pod/topology-server-7d47555bd8-pj4zs                         Unable to retrieve some image pull secrets (gcr-secret); attempting to pull the image may not succeed.
gpu-operator         41s         Warning   FailedToRetrieveImagePullSecret   pod/nvidia-dcgm-exporter-kwok-gpu-l40s-0-7b9b44f89c-dbjjm    Unable to retrieve some image pull secrets (gcr-secret); attempting to pull the image may not succeed.
gpu-operator         40s         Warning   FailedToRetrieveImagePullSecret   pod/nvidia-dcgm-exporter-kwok-gpu-a100-1-78f6456845-7zcl9    Unable to retrieve some image pull secrets (gcr-secret); attempting to pull the image may not succeed.
gpu-operator         34s         Warning   FailedToRetrieveImagePullSecret   pod/status-updater-6559cdbd76-mtcnd                          Unable to retrieve some image pull secrets (gcr-secret); attempting to pull the image may not succeed.
gpu-operator         11s         Warning   FailedToRetrieveImagePullSecret   pod/nvidia-dcgm-exporter-kwok-gpu-h100-0-b5cbf5dff-xcrwx     Unable to retrieve some image pull secrets (gcr-secret); attempting to pull the image may not succeed.
gpu-operator         7s          Warning   FailedToRetrieveImagePullSecret   pod/nvidia-dcgm-exporter-kwok-gpu-a100-0-56d7f644cd-rxqcm    Unable to retrieve some image pull secrets (gcr-secret); attempting to pull the image may not succeed.
